{"tag": "function", "depth": 2, "time": 1701612520.54744, "data": {"name": "try_log_screen", "call_args": {"screen": null, "quality": null, "max_size": null}, "start_time": 1701612520.5373085, "traceback": "Traceback (most recent call last):\n  File \"E:\\study\\daima\\tttest\\tttest_demo\\tttest-demo\\utils\\case_fromework.py\", line 19, in inner\n    args = func(*args, **kwargs)\n           ^^^^^^^^^^^^^^^^^^^^^\n  File \"E:\\study\\daima\\tttest\\tttest_demo\\tttest-demo\\testcases\\webui\\webui_cases\\test_006.py\", line 19, in test_006\n    wd.find_element(By.CSS_SELECTOR, '[aria-label=\"python\u57fa\u7840\"]').click()\n    ^^^^^^^^^^^^^^^^^^^^^^^^^^^^^^^^^^^^^^^^^^^^^^^^^^^^^^^^^^^\n  File \"E:\\TtTest\\Lib\\site-packages\\selenium\\webdriver\\remote\\webdriver.py\", line 830, in find_element\n    return self.execute(Command.FIND_ELEMENT, {\"using\": by, \"value\": value})[\"value\"]\n           ^^^^^^^^^^^^^^^^^^^^^^^^^^^^^^^^^^^^^^^^^^^^^^^^^^^^^^^^^^^^^^^^^\n  File \"E:\\TtTest\\Lib\\site-packages\\selenium\\webdriver\\remote\\webdriver.py\", line 440, in execute\n    self.error_handler.check_response(response)\n  File \"E:\\TtTest\\Lib\\site-packages\\selenium\\webdriver\\remote\\errorhandler.py\", line 245, in check_response\n    raise exception_class(message, screen, stacktrace)\nselenium.common.exceptions.NoSuchElementException: Message: no such element: Unable to locate element: {\"method\":\"css selector\",\"selector\":\"[aria-label=\"python\u57fa\u7840\"]\"}\n  (Session info: chrome=119.0.6045.200)\nStacktrace:\n\tGetHandleVerifier [0x008E72A3+45731]\n\t(No symbol) [0x00872D51]\n\t(No symbol) [0x0076880D]\n\t(No symbol) [0x0079B940]\n\t(No symbol) [0x0079BE0B]\n\t(No symbol) [0x007CD1F2]\n\t(No symbol) [0x007B8024]\n\t(No symbol) [0x007CB7A2]\n\t(No symbol) [0x007B7DD6]\n\t(No symbol) [0x007931F6]\n\t(No symbol) [0x0079439D]\n\tGetHandleVerifier [0x00BF0716+3229462]\n\tGetHandleVerifier [0x00C384C8+3523784]\n\tGetHandleVerifier [0x00C3214C+3498316]\n\tGetHandleVerifier [0x00971680+611968]\n\t(No symbol) [0x0087CCCC]\n\t(No symbol) [0x00878DF8]\n\t(No symbol) [0x00878F1D]\n\t(No symbol) [0x0086B2C7]\n\tBaseThreadInitThunk [0x76647BA9+25]\n\tRtlInitializeExceptionChain [0x77C1BD2B+107]\n\tRtlClearBits [0x77C1BCAF+191]\n\n\nDuring handling of the above exception, another exception occurred:\n\nTraceback (most recent call last):\n  File \"E:\\TtTest\\Lib\\site-packages\\airtest\\utils\\logwraper.py\", line 124, in wrapper\n    res = f(*args, **kwargs)\n          ^^^^^^^^^^^^^^^^^^\n  File \"E:\\TtTest\\Lib\\site-packages\\airtest\\core\\cv.py\", line 106, in try_log_screen\n    screen = G.DEVICE.snapshot(quality=quality)\n             ^^^^^^^^\n  File \"E:\\TtTest\\Lib\\site-packages\\airtest\\core\\helper.py\", line 19, in DEVICE\n    raise NoDeviceError(\"No devices added.\")\nairtest.core.error.NoDeviceError: 'No devices added.'\n", "end_time": 1701612520.54744}}
